Workbook
Name NativeTimeline_Start_time: #N/A
Name NativeTimeline_Start_time1: #N/A

Sheet List of Employees
A1: Employee ID | B1: Old ID | C1: Employee Name | D1: Section | E1: Status | F1: Status Change Date | G1: Level | H1: Type | I1: Full Time Emplyee | J1: Remarks
A2: 12000013 | B2: EXP-011 | C2: Atta mohamed khalil | D2: Electrical | E2: Active | G2: Manager | H2: Expat | I2: Yes
A3: 12000022 | B3: EXP-038 | C3: Hassan Metwally | D3: Electrical | E3: Active | G3: Engineer | H3: Expat | I3: Yes
A4: 12000008 | B4: EXP-037 | C4: Hany Sheta | D4: Electrical | E4: Inactive | F4: 46204 | G4: Engineer | H4: Expat | I4: Yes
A5: 12000037 | B5: EXP-169 | C5: Ahmed Hamdy | D5: Electrical | E5: Inactive | F5: 45992 | G5: Engineer | H5: Expat | I5: Yes | J5: 45992
A6: 12000042 | B6: EXP-076 | C6: Ahmad Fajar | D6: Electrical | E6: Inactive | F6: 45962 | G6: Engineer | H6: Expat | I6: Yes | J6: 45962
A7: 12000041 | B7: EXP-088 | C7: Hazwal Ngadeni | D7: Electrical | E7: Active | G7: Engineer | H7: Expat | I7: Yes
A8: 12000040 | B8: EXP-128 | C8: Filipus Aron | D8: Electrical | E8: Inactive | F8: 45992 | G8: Engineer | H8: Expat | I8: Yes | J8: 45992
A9: 12000016 | B9: EXP-155 | C9: Rohit Bhogle | D9: Electrical | E9: Inactive | F9: 45992 | G9: Engineer | H9: Expat | I9: Yes | J9: 45992
A10: 12000043 | B10: EXP-133 | C10: Asnawi bin Kariman | D10: Electrical | E10: Inactive | F10: 46362 | G10: Supervisor | H10: Expat | I10: Yes
A11: 12000027 | B11: EXP-032 | C11: Osama Abdel Azeem | D11: Electrical | E11: Active | G11: Supervisor | H11: Expat | I11: Yes
A12: 12000032 | B12: EXP-034 | C12: Moustaf Abdel Naser | D12: Electrical | E12: Inactive | F12: 45992 | G12: Supervisor | H12: Expat | I12: Yes | J12: 45992
A13: 12000067 | B13: EXP-187 | C13: Salis Nader | D13: Electrical | E13: Inactive | F13: 45992 | G13: Supervisor | H13: Expat | I13: Yes | J13: 45992
A14: 12000071 | B14: EXP-078 | C14: Suryadi Sudari Arbain | D14: Electrical | E14: Inactive | F14: 45962 | G14: Supervisor | H14: Expat | I14: Yes | J14: 45962
A15: 12000064 | B15: EXP-077 | C15: Suherman Bin Masri | D15: Electrical | E15: Active | G15: Supervisor | H15: Expat | I15: Yes
A16: 12000026 | B16: BFI-224 | C16: Hajah Nur Izzyani Binti Haji Ramlee | D16: Electrical | E16: Active | G16: Engineer | H16: Bruneian | I16: Yes
A17: 12000031 | B17: BFI-223 | C17: Muhammed Abeed Bin Sarkawi | D17: Electrical | E17: Active | G17: Engineer | H17: Bruneian | I17: Yes
A18: 12000023 | B18: BFI-249 | C18: Naadhirah Mahmud | D18: Electrical | E18: Active | G18: Engineer | H18: Bruneian | I18: Yes
A19: 12000073 | B19: BFI-226 | C19: Muhammad Nur Faris Bin Haji Buhari | D19: Electrical | E19: Active | G19: Technician | H19: Bruneian | I19: Yes
A20: 12000034 | B20: BFI-242 | C20: Muhamad Aqhari bin Jamudin | D20: Electrical | E20: Active | G20: Technician | H20: Bruneian | I20: Yes
A21: 12000036 | B21: BFI-239 | C21: Mohammad Syukri Bin Safri | D21: Electrical | E21: Active | G21: Technician | H21: Bruneian | I21: Yes
A22: 12000066 | B22: BFI-234 | C22: Mohammad Hazieduddin bin Hussin | D22: Electrical | E22: Active | G22: Technician | H22: Bruneian | I22: Yes
A23: 12000072 | B23: BFI-236 | C23: Mohamed Husnir Rahman bin Osman | D23: Electrical | E23: Active | G23: Technician | H23: Bruneian | I23: Yes
A24: 12000035 | B24: BFI-241 | C24: Liyana Abd Rahim | D24: Electrical | E24: Active | G24: Technician | H24: Bruneian | I24: Yes
A25: 12000069 | B25: BFI-240 | C25: Saharin bin Rotan | D25: Electrical | E25: Active | G25: Technician | H25: Bruneian | I25: Yes
A26: 12000029 | B26: BFI-229 | C26: Ummi Farhanah bte Zulkifle | D26: Electrical | E26: Active | G26: Technician | H26: Bruneian | I26: Yes
... A34: 12000065 | B34: BFI-238 | C34: Md Faris Zullfikeri bin Hj Abd Rashid | D34: Electrical | E34: Active | G34: Technician | H34: Bruneian | I34: Yes
A35: 12000009 | C35: Ahmed Abdelrahman Mohammed Morsy | D35: Workshop | E35: Active | G35: Manager | H35: Expat | I35: Yes
A36: 12000142 | C36: Ahmed Reda Saleh Mohamed Khalifa | D36: Workshop | E36: Inactive | F36: 46023 | G36: Engineer | H36: Expat | I36: Yes | J36: 46023
A37: 12000011 | C37: Haji Suhaimi Bin Haji Julaihi | D37: Workshop | E37: Active | G37: Engineer | H37: Bruneian | I37: Yes
A38: 12000012 | C38: Emrullah Akman | D38: Workshop | E38: Inactive | F38: 46023 | G38: Engineer | H38: Expat | I38: Yes | J38: 46023
A39: 12000154 | C39: Mohammad Taufik Bin Hassan | D39: Workshop | E39: Active | G39: Engineer | H39: Expat | I39: Yes
A40: 12000068 | C40: Hamizah Mahmud | D40: Workshop | E40: Active | G40: Engineer | H40: Bruneian | I40: Yes
A41: 12000141 | C41: Suebsak Mahintarathep | D41: Workshop | E41: Active | G41: Supervisor | H41: Expat | I41: Yes
A42: 12000160 | C42: Masdirino Bin Suradi | D42: Workshop | E42: Active | G42: Technician | H42: Bruneian | I42: Yes
A43: 12000161 | C43: Asnie Bin Idris | D43: Workshop | E43: Active | G43: Technician | H43: Bruneian | I43: Yes
A44: 12000153 | C44: Muhammad Nikmatul Faris Bin Shamsul | D44: Workshop | E44: Active | G44: Technician | H44: Bruneian | I44: Yes
A45: 12000162 | C45: Junie Bin Idris | D45: Workshop | E45: Active | G45: Technician | H45: Bruneian | I45: Yes
A46: 12000166 | C46: Muhammad Nasrullah Joey Bin Abdullah Hong | D46: Workshop | E46: Active | G46: Technician | H46: Bruneian | I46: Yes
A47: 12000165 | C47: Sukhbir Singh | D47: Workshop | E47: Active | G47: Technician | H47: Expat | I47: Yes
...

Sheet Care Card Per Employee
A1: Company / Organisation | B1: (BRE) Brunei Rotary Engineering
A2: Employee Status | B2: (Multiple Items) | C2: Max. till the Month | D2: 6
A3: Status | B3: (Multiple Items)
C4: Rectified Number
A5: Row Labels | B5: No of CARE Cards | C5: =IF(B5>$D$2,$D$2,B5) -> 6
A6: Muhammad Ali Shafie Bin Haji Ali Sabahrin | B6: 66 | C6: =IF(B6>$D$2,$D$2,B6) -> 6
A7: Ram Pratap Nishad | B7: 22 | C7: =IF(B7>$D$2,$D$2,B7) -> 6
A8: Yusof young | B8: 20 | C8: =IF(B8>$D$2,$D$2,B8) -> 6
A9: Muhammad Akmal Muntaqim bin Haji Bakeri | B9: 19 | C9: =IF(B9>$D$2,$D$2,B9) -> 6
A10: Shahminan Chamsuddin | B10: 18 | C10: =IF(B10>$D$2,$D$2,B10) -> 6
A11: Muhammad Hakim bin Abdullah | B11: 18 | C11: =IF(B11>$D$2,$D$2,B11) -> 6
A12: Mohammad Hazieduddin bin Hussin | B12: 17 | C12: =IF(B12>$D$2,$D$2,B12) -> 6
A13: Mohamed Khalil Ashalla Bagdad | B13: 16 | C13: =IF(B13>$D$2,$D$2,B13) -> 6
A14: Suebsak Mahintarathep | B14: 16 | C14: =IF(B14>$D$2,$D$2,B14) -> 6
A15: Mohd Afiq Taufiq bin Hj Mohd Talip | B15: 16 | C15: =IF(B15>$D$2,$D$2,B15) -> 6
A16: Mohd 'Arif bin Sahari | B16: 16 | C16: =IF(B16>$D$2,$D$2,B16) -> 6
A17: Muhammad Firdaus bin Muhammad Amry | B17: 15 | C17: =IF(B17>$D$2,$D$2,B17) -> 6
... A121: Grand Total | B121: 1122 | C121: =IF(B121>$D$2,$D$2,B121) -> 6
C122: =IF(B122>$D$2,$D$2,B122) -> 0
C123: =IF(B123>$D$2,$D$2,B123) -> 0
C124: =IF(B124>$D$2,$D$2,B124) -> 0

Sheet YTD Records
A1: Name | B1: YTD Number | C1: Status | D1: Employee ID
A2: ='Care Card Per Employee'!A6 -> Muhammad Ali Shafie Bin Haji Ali Sabahrin | B2: ='Care Card Per Employee'!C6 -> 6 | C2: {=_xlfn.XLOOKUP(Table7[[#This Row],[Name]],Table1[[#All],[Employee Name]],Table1[[#All],[Status]],"",0,1)} -> Active | D2: {=_xlfn.XLOOKUP(Table7[[#This Row],[Name]],Table1[[#All],[Employee Name]],Table1[[#All],[Employee ID]],"",0,1)} -> 12000148
A3: ='Care Card Per Employee'!A7 -> Ram Pratap Nishad | B3: ='Care Card Per Employee'!C7 -> 6 | C3: {=_xlfn.XLOOKUP(Table7[[#This Row],[Name]],Table1[[#All],[Employee Name]],Table1[[#All],[Status]],"",0,1)} -> Active | D3: {=_xlfn.XLOOKUP(Table7[[#This Row],[Name]],Table1[[#All],[Employee Name]],Table1[[#All],[Employee ID]],"",0,1)} -> 12000056
A4: ='Care Card Per Employee'!A8 -> Yusof young | B4: ='Care Card Per Employee'!C8 -> 6 | C4: {=_xlfn.XLOOKUP(Table7[[#This Row],[Name]],Table1[[#All],[Employee Name]],Table1[[#All],[Status]],"",0,1)} -> Active | D4: {=_xlfn.XLOOKUP(Table7[[#This Row],[Name]],Table1[[#All],[Employee Name]],Table1[[#All],[Employee ID]],"",0,1)} -> 12000104
A5: ='Care Card Per Employee'!A9 -> Muhammad Akmal Muntaqim bin Haji Bakeri | B5: ='Care Card Per Employee'!C9 -> 6 | C5: {=_xlfn.XLOOKUP(Table7[[#This Row],[Name]],Table1[[#All],[Employee Name]],Table1[[#All],[Status]],"",0,1)} -> Active | D5: {=_xlfn.XLOOKUP(Table7[[#This Row],[Name]],Table1[[#All],[Employee Name]],Table1[[#All],[Employee ID]],"",0,1)} -> 12000102
A6: ='Care Card Per Employee'!A10 -> Shahminan Chamsuddin | B6: ='Care Card Per Employee'!C10 -> 6 | C6: {=_xlfn.XLOOKUP(Table7[[#This Row],[Name]],Table1[[#All],[Employee Name]],Table1[[#All],[Status]],"",0,1)} -> Active | D6: {=_xlfn.XLOOKUP(Table7[[#This Row],[Name]],Table1[[#All],[Employee Name]],Table1[[#All],[Employee ID]],"",0,1)} -> 12000134
A7: ='Care Card Per Employee'!A11 -> Muhammad Hakim bin Abdullah | B7: ='Care Card Per Employee'!C11 -> 6 | C7: {=_xlfn.XLOOKUP(Table7[[#This Row],[Name]],Table1[[#All],[Employee Name]],Table1[[#All],[Status]],"",0,1)} -> Active | D7: {=_xlfn.XLOOKUP(Table7[[#This Row],[Name]],Table1[[#All],[Employee Name]],Table1[[#All],[Employee ID]],"",0,1)} -> 12000114
A8: ='Care Card Per Employee'!A12 -> Mohammad Hazieduddin bin Hussin | B8: ='Care Card Per Employee'!C12 -> 6 | C8: {=_xlfn.XLOOKUP(Table7[[#This Row],[Name]],Table1[[#All],[Employee Name]],Table1[[#All],[Status]],"",0,1)} -> Active | D8: {=_xlfn.XLOOKUP(Table7[[#This Row],[Name]],Table1[[#All],[Employee Name]],Table1[[#All],[Employee ID]],"",0,1)} -> 12000066
A9: ='Care Card Per Employee'!A13 -> Mohamed Khalil Ashalla Bagdad | B9: ='Care Card Per Employee'!C13 -> 6 | C9: {=_xlfn.XLOOKUP(Table7[[#This Row],[Name]],Table1[[#All],[Employee Name]],Table1[[#All],[Status]],"",0,1)} -> Active | D9: {=_xlfn.XLOOKUP(Table7[[#This Row],[Name]],Table1[[#All],[Employee Name]],Table1[[#All],[Employee ID]],"",0,1)} -> 12000010
A10: ='Care Card Per Employee'!A14 -> Suebsak Mahintarathep | B10: ='Care Card Per Employee'!C14 -> 6 | C10: {=_xlfn.XLOOKUP(Table7[[#This Row],[Name]],Table1[[#All],[Employee Name]],Table1[[#All],[Status]],"",0,1)} -> Active | D10: {=_xlfn.XLOOKUP(Table7[[#This Row],[Name]],Table1[[#All],[Employee Name]],Table1[[#All],[Employee ID]],"",0,1)} -> 12000141
A11: ='Care Card Per Employee'!A15 -> Mohd Afiq Taufiq bin Hj Mohd Talip | B11: ='Care Card Per Employee'!C15 -> 6 | C11: {=_xlfn.XLOOKUP(Table7[[#This Row],[Name]],Table1[[#All],[Employee Name]],Table1[[#All],[Status]],"",0,1)} -> Active | D11: {=_xlfn.XLOOKUP(Table7[[#This Row],[Name]],Table1[[#All],[Employee Name]],Table1[[#All],[Employee ID]],"",0,1)} -> 12000126
A12: ='Care Card Per Employee'!A16 -> Mohd 'Arif bin Sahari | B12: ='Care Card Per Employee'!C16 -> 6 | C12: {=_xlfn.XLOOKUP(Table7[[#This Row],[Name]],Table1[[#All],[Employee Name]],Table1[[#All],[Status]],"",0,1)} -> Active | D12: {=_xlfn.XLOOKUP(Table7[[#This Row],[Name]],Table1[[#All],[Employee Name]],Table1[[#All],[Employee ID]],"",0,1)} -> 12000093
A13: ='Care Card Per Employee'!A17 -> Muhammad Firdaus bin Muhammad Amry | B13: ='Care Card Per Employee'!C17 -> 6 | C13: {=_xlfn.XLOOKUP(Table7[[#This Row],[Name]],Table1[[#All],[Employee Name]],Table1[[#All],[Status]],"",0,1)} -> Active | D13: {=_xlfn.XLOOKUP(Table7[[#This Row],[Name]],Table1[[#All],[Employee Name]],Table1[[#All],[Employee ID]],"",0,1)} -> 12000202
... A116: ='Care Card Per Employee'!A120 -> Mahindra patil | B116: ='Care Card Per Employee'!C120 -> 1 | C116: {=_xlfn.XLOOKUP(Table7[[#This Row],[Name]],Table1[[#All],[Employee Name]],Table1[[#All],[Status]],"",0,1)} -> Active | D116: {=_xlfn.XLOOKUP(Table7[[#This Row],[Name]],Table1[[#All],[Employee Name]],Table1[[#All],[Employee ID]],"",0,1)} -> 12000136

Sheet HSSE Records
A1: Id | B1: Start time | C1: Completion time | D1: Email | E1: Date of Intervention / Tarikh ketika Membuat Teguran Care Card | F1: Full Name / Nama Penuh | G1: BFI Number (BFI000 / EXP000) | H1: Company / Organisation | I1: Position | J1: Location of Interventions / Lokasi tempat kamu buat teguran | K1: Purpose of Care Card Interventions / Tujuan Teguran Care Card Anda | L1: What have you Observed, Seen or Encountered? / Apa yang kamu nampak, alami atau perhatikan? | M1: What can go wrong if there's no interventions or actions has been made? / Apa boleh terjadi sekiranya tiada tindakan dilakukan? | N1: What have you done to solve the problem(s)? How did you approach the person to make interventions? / How do you support the Good Practice? What do you suggest for the Item you highlighted? / Apakah ti | O1: Category of this Care Card Submission / Kategori Teguran Care Card Anda | P1: Status | Q1: Employee Status | R1: Near Miss
A2: 7376 | B2: 46203.683 | C2: 46203.688 | D2: anonymous | E2: 46203 | F2: Mohamed Khalil Ashalla Bagdad | G2: 12000010 | H2: (BRE) Brunei Rotary Engineering | I2: RE &SE Section Manager | J2: Ammonia Plant | K2: Unsafe Condition (Dangerous Area that has potential to cause harm or injury to People within the Area) / Keadaan Bahaya | L2: A horizontal beam has been observed across the flue gas blower ladder access. head injury for personnel climbing the ladder can be occurred Re locating the beam and Painting it with a different and noticeable colour are required | M2: Injures might be happened | N2: Informing project team | O2: Design and Engineering / Tempat Pekerjaan kurang sesuai | P2: Done | Q2: {=_xlfn.XLOOKUP(Table4[[#This Row],[Full Name / Nama Penuh]],Table1[[#All],[Employee Name]],Table1[[#All],[Status]],"",0,1)} -> Active
A3: 7381 | B3: 46203.795 | C3: 46203.802 | D3: anonymous | E3: 46203 | F3: Mohammad Noorhamdillah bin Zakaria | G3: 12000081 | H3: (BRE) Brunei Rotary Engineering | I3: Mechanical rotating engineer | J3: Offsite & Utilities | K3: Unsafe Condition (Dangerous Area that has potential to cause harm or injury to People within the Area) / Keadaan Bahaya | L3: Open drain at chemical dosing skid | M3: Trip and fall hazard | N3: Suggestion to install drain cover | O3: Design and Engineering / Tempat Pekerjaan kurang sesuai | P3: Done | Q3: {=_xlfn.XLOOKUP(Table4[[#This Row],[Full Name / Nama Penuh]],Table1[[#All],[Employee Name]],Table1[[#All],[Status]],"",0,1)} -> Active
A4: 7366 | B4: 46203.487 | C4: 46203.49 | D4: anonymous | E4: 46203 | F4: Mohd Syahmi Bin Jamalluddin | G4: 12000137 | H4: (BRE) Brunei Rotary Engineering | I4: Instrument Technician | J4: North Building First Floor | K4: Unsafe Condition (Dangerous Area that has potential to cause harm or injury to People within the Area) / Keadaan Bahaya | L4: No adhesive grip tapes present on the floor of the stairs | M4: Personnel may slip and trip and they may injure themselves | N4: Informed the team that can address this issue | O4: Hazardous - Unsafe Environment / Situasi Tempat Kerja yang Berbahaya untuk Alam Sekitar | P4: Done | Q4: {=_xlfn.XLOOKUP(Table4[[#This Row],[Full Name / Nama Penuh]],Table1[[#All],[Employee Name]],Table1[[#All],[Status]],"",0,1)} -> Active
A5: 7382 | B5: 46203.802 | C5: 46203.814 | D5: anonymous | E5: 46203 | F5: Mohammad Noorhamdillah bin Zakaria | G5: 12000081 | H5: (BRE) Brunei Rotary Engineering | I5: Maintenance mechanical engineer | J5: Offsite & Utilities | K5: Safe Act or Positive Practice (An appreciation to be made to that person who shows good examples) / Kelakuan yang Baik | L5: Good housekeeping maintained at work area | M5: - | N5: Raise care card to encourage and appreciate the positive act | O5: Proactive Approach / Teguran Positif (Safe Act / Positive Act) | P5: Done | Q5: {=_xlfn.XLOOKUP(Table4[[#This Row],[Full Name / Nama Penuh]],Table1[[#All],[Employee Name]],Table1[[#All],[Status]],"",0,1)} -> Active
A6: 7377 | B6: 46203.698 | C6: 46203.704 | D6: anonymous | E6: 46203 | F6: Mohamed Othman | G6: 12000117 | H6: (BRE) Brunei Rotary Engineering | I6: Mechanical lead | J6: Urea Plant | K6: Safe Act or Positive Practice (An appreciation to be made to that person who shows good examples) / Kelakuan yang Baik | L6: Securing all granulation doors so no humidity or birds enter | M6: Birds and accumulated humidity | N6: Confirming open doors are closed | O6: Individual Behaviour / Tingkah Laku yang Cuai dan Berbahaya | P6: Done | Q6: {=_xlfn.XLOOKUP(Table4[[#This Row],[Full Name / Nama Penuh]],Table1[[#All],[Employee Name]],Table1[[#All],[Status]],"",0,1)} -> Active
A7: 7374 | B7: 46203.649 | C7: 46203.652 | D7: anonymous | E7: 46203 | F7: Liyana Abd Rahim | G7: 12000035 | H7: (BRE) Brunei Rotary Engineering | I7: Technician | J7: Offsite & Utilities | K7: Improvement Suggestions / Cadangan untuk diperbaiki | L7: Someone falling down from bicycle because of blue cable | M7: More people will fall down | N7: Give suggestion | O7: Design and Engineering / Tempat Pekerjaan kurang sesuai | P7: Done | Q7: {=_xlfn.XLOOKUP(Table4[[#This Row],[Full Name / Nama Penuh]],Table1[[#All],[Employee Name]],Table1[[#All],[Status]],"",0,1)} -> Active
A8: 7365 | B8: 46203.477 | C8: 46203.487 | D8: anonymous | E8: 46203 | F8: Mohd Syahmi Bin Jamalluddin | G8: 12000137 | H8: (BRE) Brunei Rotary Engineering | I8: Instrument Technician | J8: Site Office First Floor | K8: Improvement Suggestions / Cadangan untuk diperbaiki | L8: No adhesive grip tapes on the stairs | M8: People may slip and injure themselves | N8: Raise this concern to the respective party to address this issue | O8: Hazardous - Unsafe Environment / Situasi Tempat Kerja yang Berbahaya untuk Alam Sekitar | P8: Done | Q8: {=_xlfn.XLOOKUP(Table4[[#This Row],[Full Name / Nama Penuh]],Table1[[#All],[Employee Name]],Table1[[#All],[Status]],"",0,1)} -> Active
A9: 7354 | B9: 46203.333 | C9: 46203.347 | D9: anonymous | E9: 46202 | F9: Naadhirah Mahmud | G9: 12000023 | H9: (BRE) Brunei Rotary Engineering | I9: Electrical Engineer | J9: Offsite & Utilities | K9: Unsafe Act (Dangerous or Unsafe Act that was done by someone) / Perbuatan Bahaya | L9: i saw someone texting while walking. | M9: she could fall because she was not paying attention. | N9: informed the person to step aside and reply to texts rather than texting while walking. | O9: Individual Behaviour / Tingkah Laku yang Cuai dan Berbahaya | P9: Done | Q9: {=_xlfn.XLOOKUP(Table4[[#This Row],[Full Name / Nama Penuh]],Table1[[#All],[Employee Name]],Table1[[#All],[Status]],"",0,1)} -> Active
A10: 7313 | B10: 46202.58 | C10: 46202.584 | D10: anonymous | E10: 46202 | F10: Shamiza binti Hussin | G10: 12000025 | H10: (BRE) Brunei Rotary Engineering | I10: Electrical Technician | J10: Site Office First Floor | K10: Unsafe Act (Dangerous or Unsafe Act that was done by someone) / Perbuatan Bahaya | L10: a personel was seen going upstair with his shoelace undone | M10: he may slip, trip and fall | N10: stop him and ask him to tie his shoelace | O10: Individual Behaviour / Tingkah Laku yang Cuai dan Berbahaya | P10: Done | Q10: {=_xlfn.XLOOKUP(Table4[[#This Row],[Full Name / Nama Penuh]],Table1[[#All],[Employee Name]],Table1[[#All],[Status]],"",0,1)} -> Active
A11: 7339 | B11: 46203.257 | C11: 46203.259 | D11: anonymous | E11: 46202 | F11: Mohammad Nabil Haji Gapor | G11: 12000044 | H11: (BRE) Brunei Rotary Engineering | I11: Lead Electrical Technician | J11: Trailer Parking Area | K11: Unsafe Condition (Dangerous Area that has potential to cause harm or injury to People within the Area) / Keadaan Bahaya | L11: almost got bitten by the dogs | M11: someone get bitten | N11: catch the dog and put them somewhere safer and better | O11: Hazardous - Unsafe Materials / Benda yang Berbahaya | P11: Done | Q11: {=_xlfn.XLOOKUP(Table4[[#This Row],[Full Name / Nama Penuh]],Table1[[#All],[Employee Name]],Table1[[#All],[Status]],"",0,1)} -> Active
A12: 7307 | B12: 46202.511 | C12: 46202.513 | D12: anonymous | E12: 46202 | F12: Vinod Kumar Verma | G12: 12000050 | H12: (BRE) Brunei Rotary Engineering | I12: Rotating technician | J12: North Building Ground Floor | K12: Unsafe Condition (Dangerous Area that has potential to cause harm or injury to People within the Area) / Keadaan Bahaya | L12: drainage water came out | M12: smell slip trip fall | N12: please inform to vaccum truck and clean this pit | O12: Hazardous - Unsafe Materials / Benda yang Berbahaya | P12: Done | Q12: {=_xlfn.XLOOKUP(Table4[[#This Row],[Full Name / Nama Penuh]],Table1[[#All],[Employee Name]],Table1[[#All],[Status]],"",0,1)} -> Active
A13: 7315 | B13: 46202.715 | C13: 46202.72 | D13: anonymous | E13: 46202 | F13: Ti Zhi Yuan | G13: 12000109 | H13: (BRE) Brunei Rotary Engineering | I13: Static Engineer | J13: Car Park near North Building | K13: Unsafe Act (Dangerous or Unsafe Act that was done by someone) / Perbuatan Bahaya | L13: Driving fast at car park area | M13: Accident causing minor/serious injury to passerby | N13: Intervene the driver to follow the speed limit | O13: Individual Behaviour / Tingkah Laku yang Cuai dan Berbahaya | P13: Done | Q13: {=_xlfn.XLOOKUP(Table4[[#This Row],[Full Name / Nama Penuh]],Table1[[#All],[Employee Name]],Table1[[#All],[Status]],"",0,1)} -> Active
... A165: 7061 | B165: 46181.433 | C165: 46181.438 | D165: anonymous | E165: 46181 | F165: Masdirino Bin Suradi | G165: 12000160 | H165: (BRE) Brunei Rotary Engineering | I165: HVAC TECHNICIAN | J165: Workshop | K165: Unsafe Condition (Dangerous Area that has potential to cause harm or injury to People within the Area) / Keadaan Bahaya | L165: Discovered that the safety interlocking guard on the fabrication workshop milling machine was bypassed with tape, allowing the machine to operate while the protective shield was wide open. | M165: Operators could easily make accidental contact with high-speed rotating parts, leading to severe lacerations, entanglement, or traumatic amputation of limbs. | N165: Enforced immediate machine shutdown and applied a Lockout/Tagout (LOTO) tag. Confronted the operator regarding the life-saving rule violation and raised the issue to the Workshop Supervisor. | O165: Tools, Equipment and Machinery / Berkaitan dengan Alat Kegunaan Pekerjaan dan Mesin sama ada ianya Tidak Sesuai untuk aktivitas tersebut atau sebaliknya | P165: Done | Q165: {=_xlfn.XLOOKUP(Table4[[#This Row],[Full Name / Nama Penuh]],Table1[[#All],[Employee Name]],Table1[[#All],[Status]],"",0,1)} -> Active
A166: 5889 | B166: 46120.552 | C166: 46120.554 | D166: anonymous | E166: 46181 | F166: Yusof young | H166: (BRE) Brunei Rotary Engineering | I166: static | J166: Ammonia Plant | K166: Safe Act or Positive Practice (An appreciation to be made to that person who shows good examples) / Kelakuan yang Baik | L166: co worker following the required safety regulation from the permit to work suggested by the pip | M166: N/A | N166: tell him to keep it up | O166: Proactive Approach / Teguran Positif (Safe Act / Positive Act) | P166: Done | Q166: {=_xlfn.XLOOKUP(Table4[[#This Row],[Full Name / Nama Penuh]],Table1[[#All],[Employee Name]],Table1[[#All],[Status]],"",0,1)} -> Active
A167: 7196 | B167: 46195.629 | C167: 46195.629 | D167: anonymous | E167: 46181 | F167: Ram Pratap Nishad | G167: 12000056 | H167: (BRE) Brunei Rotary Engineering | I167: Senior Static Technician | J167: Ammonia Plant | K167: Safe Act or Positive Practice (An appreciation to be made to that person who shows good examples) / Kelakuan yang Baik | L167: 1071P002A, pump suction strainer cleaning work | M167: Safe working behaviour found | N167: Safe work | O167: Individual Behaviour / Tingkah Laku yang Cuai dan Berbahaya | P167: Done | Q167: {=_xlfn.XLOOKUP(Table4[[#This Row],[Full Name / Nama Penuh]],Table1[[#All],[Employee Name]],Table1[[#All],[Status]],"",0,1)} -> Active
A168: 7100 | B168: 46184.484 | C168: 46184.487 | D168: anonymous | E168: 46181 | F168: Abdul Khaliq Haji Adinin | G168: 12000112 | H168: (BRE) Brunei Rotary Engineering | I168: Static Technician | J168: Main Gate 1 | K168: Safe Act or Positive Practice (An appreciation to be made to that person who shows good examples) / Kelakuan yang Baik | L168: Saw security personal intervene one contractor personal where he’s about to go inside the site with rolled up sleeves, where it does not met proper attire etiquette | M168: Not using proper PPE is a violation and also can cause harm whenever he’s inside the plant since there’s a lot of hazard around the area | N168: Praise the security personal as he intervene in good and safe manner to the personal | O168: Proactive Approach / Teguran Positif (Safe Act / Positive Act) | P168: Done | Q168: {=_xlfn.XLOOKUP(Table4[[#This Row],[Full Name / Nama Penuh]],Table1[[#All],[Employee Name]],Table1[[#All],[Status]],"",0,1)} -> Active
A169: 7072 | B169: 46181.539 | C169: 46181.543 | D169: anonymous | E169: 46181 | F169: Dk NoorFaszalenna Pg Zaini | G169: 12000024 | H169: (BRE) Brunei Rotary Engineering | I169: Electrical Technician | J169: Electrical Substation | K169: Safe Act or Positive Practice (An appreciation to be made to that person who shows good examples) / Kelakuan yang Baik | L169: Saw a personnel stopping another person who is working on electrical equipment to use handgloves | M169: - | N169: - | O169: Proactive Approach / Teguran Positif (Safe Act / Positive Act) | P169: Done | Q169: {=_xlfn.XLOOKUP(Table4[[#This Row],[Full Name / Nama Penuh]],Table1[[#All],[Employee Name]],Table1[[#All],[Status]],"",0,1)} -> Active
A170: 7070 | B170: 46181.522 | C170: 46181.53 | D170: anonymous | E170: 46181 | F170: Jaosoa Francklin | G170: 12000156 | H170: (BRE) Brunei Rotary Engineering | I170: Valve Technician | J170: Workshop | K170: Improvement Suggestions / Cadangan untuk diperbaiki | L170: Currently we notice more and more bird comes and dwelled inside MSL workshop. Though we have sensitive Equipment inside. And our devices are likely covered by bird excrements. | M170: Fore sure we clean but this can affect life time and efficiency if reached critical parts | N170: we are trying to keep equipment as clean as possible and covered them after shift but it become complicate since more bird live inside. | O170: Facility Management / Perawatan Kemudahan dan Aset | P170: Done | Q170: {=_xlfn.XLOOKUP(Table4[[#This Row],[Full Name / Nama Penuh]],Table1[[#All],[Employee Name]],Table1[[#All],[Status]],"",0,1)} -> Active
A171: 5889 | B171: 46120.552 | C171: 46120.554 | D171: anonymous | E171: 46181 | F171: Yusof young | G171: 12000104 | H171: (BRE) Brunei Rotary Engineering | I171: static | J171: Ammonia Plant | K171: Safe Act or Positive Practice (An appreciation to be made to that person who shows good examples) / Kelakuan yang Baik | L171: co worker following the required safety regulation from the permit to work suggested by the pip | M171: N/A | N171: tell him to keep it up | O171: Proactive Approach / Teguran Positif (Safe Act / Positive Act) | P171: Done | Q171: {=_xlfn.XLOOKUP(Table4[[#This Row],[Full Name / Nama Penuh]],Table1[[#All],[Employee Name]],Table1[[#All],[Status]],"",0,1)} -> Active
A172: 7056 | B172: 46180.667 | C172: 46180.67 | D172: anonymous | E172: 46180 | F172: Saharin bin Rotan | G172: 12000069 | H172: (BRE) Brunei Rotary Engineering | I172: Electrical technician | J172: Site Office First Floor | K172: Safe Act or Positive Practice (An appreciation to be made to that person who shows good examples) / Kelakuan yang Baik | L172: Cleaner doing the cleaning and put the signage's on the entrance so people aware there is cleaning activity | N172: Keep up your good works and it inspire me to keep my office tidy | O172: Proactive Approach / Teguran Positif (Safe Act / Positive Act) | P172: Done | Q172: {=_xlfn.XLOOKUP(Table4[[#This Row],[Full Name / Nama Penuh]],Table1[[#All],[Employee Name]],Table1[[#All],[Status]],"",0,1)} -> Active
A173: 7140 | B173: 46191.265 | C173: 46191.272 | D173: anonymous | E173: 46179 | F173: Muhd Hishamuddin bin Edis Asmena | G173: 12000088 | H173: (BRE) Brunei Rotary Engineering | I173: Instrument Technician Shift | J173: Site Office's Staffs Rest Area | K173: Unsafe Act (Dangerous or Unsafe Act that was done by someone) / Perbuatan Bahaya | L173: Several bicycles were found parked in the site cabin area. It was noted that some bicycles had missing parts, suspected to have been stolen by unknown person (unauthorized removal). | M173: if no action is taken could be stated as: -Continued theft of bicycle parts or entire bicycles, resulting in further property losses. -Reduced employee morale and trust due to concerns about personal property security. | N173: -Install CCTV cameras or improve surveillance coverage around the bicycle parking area. -Enhance lighting in the site cabin area to improve visibility, especially during non-working hours. -Encourage bicycle owners to use locks and secure their bicycles properly. -Conduct regular security patrols and inspections of the parking area. | O173: Individual Behaviour / Tingkah Laku yang Cuai dan Berbahaya | P173: Done | Q173: {=_xlfn.XLOOKUP(Table4[[#This Row],[Full Name / Nama Penuh]],Table1[[#All],[Employee Name]],Table1[[#All],[Status]],"",0,1)} -> Active
A174: 7050 | B174: 46178.46 | C174: 46178.466 | D174: anonymous | E174: 46178 | F174: Ahmed Abdelfattah Ahmed Aly Shaaban | G174: 12000019 | H174: (BRE) Brunei Rotary Engineering | I174: Urea rotating lead | J174: Urea Plant | K174: Unsafe Condition (Dangerous Area that has potential to cause harm or injury to People within the Area) / Keadaan Bahaya | L174: Acid leak from acid dosing unit to ground , a lot of chemical mats used to absorb and containment but no prober house keeping for these mats frequently until leak repair done. | M174: Acid covering the ground area , where all operation and maintenance doing activities | N174: Informed site operator to ask thier contractor ( brudesh) to do prober house keeping for the area and disposal for the mats full of acid and to inform environment team | O174: Hazardous - Unsafe Materials / Benda yang Berbahaya | P174: Done | Q174: {=_xlfn.XLOOKUP(Table4[[#This Row],[Full Name / Nama Penuh]],Table1[[#All],[Employee Name]],Table1[[#All],[Status]],"",0,1)} -> Active
A175: 7054 | B175: 46179.31 | C175: 46179.314 | D175: anonymous | E175: 46178 | F175: Abu bakar ali | G175: 12000234 | H175: (BRE) Brunei Rotary Engineering | I175: Welder | J175: Urea Plant | K175: Unsafe Condition (Dangerous Area that has potential to cause harm or injury to People within the Area) / Keadaan Bahaya | L175: Open hole scaffolding floor. | M175: Somebody will fall to the hole and can get serious injury. | N175: Call scaffolding supv for immediately close the hole. | O175: Hazardous - Unsafe Environment / Situasi Tempat Kerja yang Berbahaya untuk Alam Sekitar | P175: Not BRE | Q175: {=_xlfn.XLOOKUP(Table4[[#This Row],[Full Name / Nama Penuh]],Table1[[#All],[Employee Name]],Table1[[#All],[Status]],"",0,1)}
A176: 7053 | B176: 46179.297 | C176: 46179.302 | D176: anonymous | E176: 46178 | F176: Abu bakar ali | G176: 12000234 | H176: (BRE) Brunei Rotary Engineering | I176: Welder | J176: Workshop | K176: Unsafe Act (Dangerous or Unsafe Act that was done by someone) / Perbuatan Bahaya | L176: During grinding the spark are pointing to other workers. | M176: Flying spark can cause eye injury. | N176: Stop the worker, change the direction and grinding positions to other side which no body around that area. | O176: Position of People / Keberadaan seseorang ketika bekerja (Line of Fire, Drop Object & Slip, Trip and Fall) | P176: Not BRE | Q176: {=_xlfn.XLOOKUP(Table4[[#This Row],[Full Name / Nama Penuh]],Table1[[#All],[Employee Name]],Table1[[#All],[Status]],"",0,1)}
A177: 7051 | B177: 46178.467 | C177: 46178.472 | D177: anonymous | E177: 46178 | F177: Ahmed Abdelfattah Ahmed Aly Shaaban | G177: 12000019 | H177: (BRE) Brunei Rotary Engineering | I177: Urea rotating lead | J177: Urea Plant | K177: Safe Act or Positive Practice (An appreciation to be made to that person who shows good examples) / Kelakuan yang Baik | L177: Prober handling & disposal for oil after maintenance activities completion by urea rotating team | M177: Non prober handling and disposal will lead to oil spillage, slip& trip wich may lead to injury | N177: Appreciated the urea rotating team effort and encouraged for keep the same practice | O177: Hazardous - Unsafe Materials / Benda yang Berbahaya | P177: Done | Q177: {=_xlfn.XLOOKUP(Table4[[#This Row],[Full Name / Nama Penuh]],Table1[[#All],[Employee Name]],Table1[[#All],[Status]],"",0,1)} -> Active
A178: 7049 | B178: 46178.456 | C178: 46178.459 | D178: anonymous | E178: 46178 | F178: Muhammad Ali Shafie Bin Haji Ali Sabahrin | G178: 12000148 | H178: (BRE) Brunei Rotary Engineering | I178: Welder | J178: Workshop | K178: Safe Act or Positive Practice (An appreciation to be made to that person who shows good examples) / Kelakuan yang Baik | L178: I've seen my supervisor is doing a material preparation for next week task. | M178: - Work stops mid-task: You get halfway and realize you’re missing wire, fittings, or fasteners. Job stalls until procurement delivers - Schedule slips: Waiting on materials pushes deadlines and affects other teams that depend on you - Rush orders & higher cost: Last-minute buys mean paying express shipping or premium prices - Wrong substitutes used: People grab “close enough” materials to keep moving. That risks quality, performance, or safety - Idle time for the crew: Techs stand around or get pulled to low-value work. Morale and productivity drop - Rework later: If wrong or substandard materials were used to save time, you’ll redo the job later - Poor coordination: Other teams, contractors, or vendors show up ready but can’t proceed. Creates friction between departments - Safety gaps: Improvising with wrong materials in electrical/mechanical work increases incident risk | N178: - Review next week’s job list every Friday: Sit 10 min with the team/supervisor and list what’s needed for each task - Check stock vs. plan: Walk the store and compare BOM/material list to what’s on hand. Flag shortages early - Use a simple material prep checklist: Include item, qty, location, and who checks it. Post it near the job board - Raise PR/MR early: Submit requests by Friday morning so procurement and store have time to react - Pre-kitting: Pull and stage all materials for each job in a labeled bin/trolley. Monday starts with “grab and go” - Confirm with other teams: Quick check with instrument, electrical, mechanical that they’ve got what they need too - Assign ownership: Make one person responsible for prep and follow-up, not “everyone” - Log common shortages: Track what’s always missing and push for buffer stock or faster re-order points - Do a 5-min handover: End of Friday, confirm what’s ready and what’s pending. No surprises Monday morning | O178: Proactive Approach / Teguran Positif (Safe Act / Positive Act) | P178: Done | Q178: {=_xlfn.XLOOKUP(Table4[[#This Row],[Full Name / Nama Penuh]],Table1[[#All],[Employee Name]],Table1[[#All],[Status]],"",0,1)} -> Active
A179: 7048 | B179: 46178.441 | C179: 46178.445 | D179: anonymous | E179: 46178 | F179: Suebsak Mahintarathep | G179: 12000141 | H179: (BRE) Brunei Rotary Engineering | I179: Mechanical Maintenance supervisor | J179: Workshop | K179: Safe Act or Positive Practice (An appreciation to be made to that person who shows good examples) / Kelakuan yang Baik | L179: Workshop team do fabrication new pipe spool , after they cut they keep pipe material on ground near working area | M179: They can slip & trip form pipe spools | N179: I inform them to move pipe spools out from working area | O179: Hazardous - Unsafe Materials / Benda yang Berbahaya | P179: Done | Q179: {=_xlfn.XLOOKUP(Table4[[#This Row],[Full Name / Nama Penuh]],Table1[[#All],[Employee Name]],Table1[[#All],[Status]],"",0,1)} -> Active
A180: 7046 | B180: 46178.384 | C180: 46178.396 | D180: anonymous | E180: 46178 | F180: Muhammad Ali Shafie Bin Haji Ali Sabahrin | G180: 12000148 | H180: (BRE) Brunei Rotary Engineering | I180: Welder | J180: Workshop | K180: Safe Act or Positive Practice (An appreciation to be made to that person who shows good examples) / Kelakuan yang Baik | L180: Doing housekeeping before having off day during the weekend. | M180: - Trip and fall hazards: Tools, cables, offcuts left out become risks when people rush back in Monday morning 🚶‍♂️ - Fire risk: Oily rags, dust, flammable offcuts left near power sources or heat can smolder unattended - Equipment damage: Dust, metal swarf, and coolant get into machines and control panels, causing faults or seizure - Pest problems: Food scraps and waste attract rats, cockroaches, and ants over the weekend - Lost/misplaced tools: Messy benches make it easy to lose items, so Monday starts with hunting instead of working - Corrosion and spoilage: Metal parts left dirty or wet start rusting. Materials get contaminated or unusable - Safety audit failures: Messy workshop = non-compliance with HSE standards. Fines or stop-work orders possible - Lower morale: Coming back to a messy space kills motivation and makes people less careful - Hidden damage: Leaks, cracks, or worn parts stay hidden under debris until they become bigger problems Bottom line: 15 min of housekeeping Friday saves you time, money, and safety headaches on Monday | N180: - Use a 5-min end-of-shift checklist: Post a simple list by the exit/DB: clear benches, store tools, bin waste, wipe machines, check for leaks - Assign “last man out”: Rotate the role so one person does a quick walkthrough and signs off. No guessing who’s responsible - Make it visible: Use shadow boards and labeled storage so putting things back takes 10 sec, not 2 min - Keep cleaning tools handy: Brooms, bins, rags, degreaser within arm’s reach. If it’s far, it won’t get used - Tie it to safety: Start toolbox talks with near-misses from poor housekeeping. Makes the “why” obvious - Supervisors check and reinforce: A quick “thanks, area looks good” goes further than scolding. Recognition builds habit - Do a Friday 15-min push: Block 15 min before knock-off for everyone to clean their zone. Treat it like part of the job, not overtime - Make it a handover item: If the next shift finds a mess, log it. If it’s clean, log that too. Accountability works both ways - Remove excuses: Provide enough bins, storage, and disposal routes so people don’t leave stuff “just for now” Bottom line: When housekeeping is quick, visible, and owned by the crew, it stops being a chore and becomes the way you leave the place. | O180: Proactive Approach / Teguran Positif (Safe Act / Positive Act) | P180: Done | Q180: {=_xlfn.XLOOKUP(Table4[[#This Row],[Full Name / Nama Penuh]],Table1[[#All],[Employee Name]],Table1[[#All],[Status]],"",0,1)} -> Active
A181: 7067 | B181: 46181.496 | C181: 46181.499 | D181: anonymous | E181: 46177 | F181: Muhamad Aqhari bin Jamudin | G181: 12000034 | H181: (BRE) Brunei Rotary Engineering | I181: Technician | J181: Urea Plant | K181: Unsafe Condition (Dangerous Area that has potential to cause harm or injury to People within the Area) / Keadaan Bahaya | L181: Found rubbish on main screen floor at granulation | M181: Unwanted pest like rat could appeared | N181: Throw the rubbish to appropriate bin | O181: Waste Management / Berkaitan dengan Pengurusan Pembuangan Sampah | P181: Done | Q181: {=_xlfn.XLOOKUP(Table4[[#This Row],[Full Name / Nama Penuh]],Table1[[#All],[Employee Name]],Table1[[#All],[Status]],"",0,1)} -> Active
A182: 7099 | B182: 46184.463 | C182: 46184.469 | D182: anonymous | E182: 46177 | F182: Asnie Bin Idris | G182: 12000161 | H182: (BRE) Brunei Rotary Engineering | I182: DE Technician | J182: Jetty Head | K182: Unsafe Condition (Dangerous Area that has potential to cause harm or injury to People within the Area) / Keadaan Bahaya | L182: requires proper housekeeping around the EDG area | M182: if want to check and emergency start the generator engine it is difficult to access the engine area | N182: inform ops to do proper house keeping | O182: Material Arrangement and Housekeeping / Kesesuaian Penyusunan Barang dan Kebersihan Tempat Pekerjaan | P182: Done | Q182: {=_xlfn.XLOOKUP(Table4[[#This Row],[Full Name / Nama Penuh]],Table1[[#All],[Employee Name]],Table1[[#All],[Status]],"",0,1)} -> Active
A183: 7165 | B183: 46191.666 | C183: 46191.677 | D183: anonymous | E183: 46177 | F183: Mohd Habibullah bin Mohd Adnan Izan | G183: 12000131 | H183: (BRE) Brunei Rotary Engineering | I183: Instrument Shift Technician | J183: Ammonia Plant | K183: Safe Act or Positive Practice (An appreciation to be made to that person who shows good examples) / Kelakuan yang Baik | L183: One of the Control Valve has Ammonia Liquid Leak at the gland packing. Required to be tighten. | M183: After the permit was done. If I just go and tighen the gland packing without specific PPEs and without any information of the media on the pipeline. I would expose myself to the Ammonia Liquid. As it was also strong smell of Ammonia around the area. | N183: I discussed with the Operation Team and the Safety Officer. The task required to wear the specific PPEs, such as Chemical gloves, Goggles and Gas Respirator. I wore the speficic PPEs before performing the task. | O183: Hazardous - Unsafe Materials / Benda yang Berbahaya | P183: Done | Q183: {=_xlfn.XLOOKUP(Table4[[#This Row],[Full Name / Nama Penuh]],Table1[[#All],[Employee Name]],Table1[[#All],[Status]],"",0,1)} -> Active
A184: 7164 | B184: 46191.643 | C184: 46191.643 | D184: anonymous | E184: 46177 | F184: Muhammad Akmal Muntaqim bin Haji Bakeri | G184: 12000102 | H184: (BRE) Brunei Rotary Engineering | I184: Mechanical Technician | J184: Warehouse | K184: Improvement Suggestions / Cadangan untuk diperbaiki | L184: Observed theres no enough ventilation at granulation house at screen shaker area | M184: Fatigue, headaches, severe allergy or asthma flareup | N184: Inspect exhaust and dust extraction system or make an open window or door for the airway | O184: Design and Engineering / Tempat Pekerjaan kurang sesuai | P184: Done | Q184: {=_xlfn.XLOOKUP(Table4[[#This Row],[Full Name / Nama Penuh]],Table1[[#All],[Employee Name]],Table1[[#All],[Status]],"",0,1)} -> Active
... A212: 6942 | B212: 46171.299 | C212: 46171.301 | D212: anonymous | E212: 46171 | F212: Nurul Ainul Hayat bin Abdul Majid | G212: 12000097 | H212: (BRE) Brunei Rotary Engineering | I212: Rotating Technician | J212: Offsite & Utilities | K212: Unsafe Condition (Dangerous Area that has potential to cause harm or injury to People within the Area) / Keadaan Bahaya | L212: Mainhole open space nearby cooling water pump | M212: Fall inside mainhole | N212: Provide barricade and immediately provide cover mainhole | O212: Signage and Barriers / Papan Tanda dan Perbatasan Keselamatan tempat kerja | P212: Done | Q212: {=_xlfn.XLOOKUP(Table4[[#This Row],[Full Name / Nama Penuh]],Table1[[#All],[Employee Name]],Table1[[#All],[Status]],"",0,1)} -> Inactive
A213: 6946 | B213: 46171.353 | C213: 46171.355 | D213: anonymous | E213: 46171 | F213: Mahindra patil | H213: (BRE) Brunei Rotary Engineering | I213: Static technician | J213: Jetty Head | K213: Unsafe Condition (Dangerous Area that has potential to cause harm or injury to People within the Area) / Keadaan Bahaya | L213: Platform bolt missing | M213: Slip trip fall | N213: Please inform to workshop team install missing bolts | O213: Design and Engineering / Tempat Pekerjaan kurang sesuai | P213: Done | Q213: {=_xlfn.XLOOKUP(Table4[[#This Row],[Full Name / Nama Penuh]],Table1[[#All],[Employee Name]],Table1[[#All],[Status]],"",0,1)} -> Active
A214: 6952 | B214: 46171.394 | C214: 46171.397 | D214: anonymous | E214: 46171 | F214: Mohd Syahmi Bin Jamalluddin | G214: 12000137 | H214: (BRE) Brunei Rotary Engineering | I214: Instrument Technician | J214: Ammonia Plant | K214: Unsafe Act (Dangerous or Unsafe Act that was done by someone) / Perbuatan Bahaya | L214: The person going up the stairs without holding the handrails | M214: That person may fall and get injured | N214: Approached the person nicely and tell them to hold the handrails to prevent injuries if they slip | O214: Individual Behaviour / Tingkah Laku yang Cuai dan Berbahaya | P214: Done | Q214: {=_xlfn.XLOOKUP(Table4[[#This Row],[Full Name / Nama Penuh]],Table1[[#All],[Employee Name]],Table1[[#All],[Status]],"",0,1)} -> Active
A215: 6964 | B215: 46171.447 | C215: 46171.45 | D215: anonymous | E215: 46171 | F215: Mohammad Raimi bin Mohammad | G215: 12000070 | H215: (BRE) Brunei Rotary Engineering | I215: Electrical Shift Technician | J215: Plant Entry Gate | K215: Unsafe Act (Dangerous or Unsafe Act that was done by someone) / Perbuatan Bahaya | L215: driver didnt follow the designated roundabout and drove straight instead circulating in right direction. | M215: car accident | N215: advice the driver to follow the correct roundabout route | O215: Individual Behaviour / Tingkah Laku yang Cuai dan Berbahaya | P215: Done | Q215: {=_xlfn.XLOOKUP(Table4[[#This Row],[Full Name / Nama Penuh]],Table1[[#All],[Employee Name]],Table1[[#All],[Status]],"",0,1)} -> Active
A216: 6974 | B216: 46171.711 | C216: 46171.712 | D216: anonymous | E216: 46171 | F216: Nur Muhammad Bin Awang Kasim | G216: 12000125 | H216: (BRE) Brunei Rotary Engineering | I216: Technician | J216: Unsure / Kurang Pasti | K216: Unsafe Act (Dangerous or Unsafe Act that was done by someone) / Perbuatan Bahaya | L216: Reckless driving | M216: Accident | N216: Tell the driver to drive more carefully | O216: Individual Behaviour / Tingkah Laku yang Cuai dan Berbahaya | P216: Done | Q216: {=_xlfn.XLOOKUP(Table4[[#This Row],[Full Name / Nama Penuh]],Table1[[#All],[Employee Name]],Table1[[#All],[Status]],"",0,1)} -> Active
A217: 6976 | B217: 46172.083 | C217: 46172.093 | D217: anonymous | E217: 46171 | F217: Abu bakar ali | G217: 12000234 | H217: (BRE) Brunei Rotary Engineering | I217: Welder | J217: Ammonia Storage Tank Area | K217: Unsafe Condition (Dangerous Area that has potential to cause harm or injury to People within the Area) / Keadaan Bahaya | L217: Scaffolding inspection tag expired | M217: Some body will use that scaffolding without be inspected by scaffolding supv, afraid some modifications made by the other workers using it. | N217: Always check the tags before use the scaffolding for safety reasons. | O217: Position of People / Keberadaan seseorang ketika bekerja (Line of Fire, Drop Object & Slip, Trip and Fall) | P217: Not BRE | Q217: {=_xlfn.XLOOKUP(Table4[[#This Row],[Full Name / Nama Penuh]],Table1[[#All],[Employee Name]],Table1[[#All],[Status]],"",0,1)}
A218: 6987 | B218: 46173.558 | C218: 46173.56 | D218: anonymous | E218: 46171 | F218: Liyana Abd Rahim | G218: 12000035 | H218: (BRE) Brunei Rotary Engineering | I218: Electrical Technician | J218: Urea Plant | K218: Unsafe Condition (Dangerous Area that has potential to cause harm or injury to People within the Area) / Keadaan Bahaya | L218: Ammonia Smell but no signage seen in the area | M218: Many people will inhale the smell | N218: Put barricade | O218: Hazardous - Unsafe Environment / Situasi Tempat Kerja yang Berbahaya untuk Alam Sekitar | P218: Done | Q218: {=_xlfn.XLOOKUP(Table4[[#This Row],[Full Name / Nama Penuh]],Table1[[#All],[Employee Name]],Table1[[#All],[Status]],"",0,1)} -> Active
...

Sheet CARE Card KPI Value
B1: Pillar | C1: KPI Name | D1: KPI Definition | E1: 2025 | Q1: 2026
E2: 25-Apr | F2: 25-May | G2: 25-Jun | H2: Q2 | I2: 25-Jul | J2: 25-Aug | K2: 25-Sep | L2: Q3 | M2: 25-Oct | N2: 25-Nov | O2: 25-Dec | P2: Q4 | Q2: 26-Jan | R2: 26-Feb | S2: 26-Mar | T2: Q1 | U2: 26-Apr | V2: 26-May | W2: 46199 | X2: Q2 | Y2: 46229 | Z2: 46260 | AA2: 46291 | AB2: Q3 | AC2: 46321 | AD2: 46352 | AE2: 46382 | AF2: Q4
B3: HSE | C3: Total Number of CARE Cards (Monthly) | D3: KPI Guideline | E3: 184 | F3: 182 | G3: 137 | H3: =SUM(E3:G3) -> 503 | I3: 351 | J3: 351 | K3: 201 | L3: =SUM(I3:K3) -> 903 | M3: 464 | N3: 259 | O3: 218 | P3: 482 | Q3: 100 | R3: 98 | S3: 173 | T3: 566 | U3: 234 | V3: 197 | W3: 169 | X3: 665 | Y3: 242 | Z3: 242 | AA3: 242 | AB3: 726 | AC3: 242 | AD3: 242 | AE3: 242 | AF3: 726
C4: Number of Employees (Monthly) | E4: 151 | F4: 151 | G4: 151 | H4: 151 | I4: 151 | J4: 151 | K4: 151 | L4: 151 | M4: 151 | N4: 148 | O4: 121 | P4: 121 | Q4: 121 | R4: 121 | S4: 121 | T4: 121 | U4: 121 | V4: 122 | W4: 121 | X4: 115 | Y4: 121 | Z4: 121 | AA4: 121 | AB4: 121 | AC4: 121 | AD4: 121 | AE4: 121 | AF4: 121
C5: Number of CARE Cards per Employee (Monthly) | E5: =MIN(E3/E4,2) -> 1.218543 | F5: =MIN(F3/F4,2) -> 1.205298 | G5: =MIN(G3/G4,2) -> 0.90728477 | H5: =MIN(H3/(H4*3),2) -> 1.1103753 | I5: =MIN(I3/I4,2) -> 2 | J5: =MIN(J3/J4,2) -> 2 | K5: =MIN(K3/K4,2) -> 1.3311258 | L5: =MIN(L3/(L4*3),2) -> 1.9933775 | M5: =MIN(M3/M4,2) -> 2 | N5: =MIN(N3/N4,2) -> 1.75 | O5: =MIN(O3/O4,2) -> 1.8016529 | P5: =MIN(P3/(P4*3),2) -> 1.3278237 | Q5: =MIN(Q3/Q4,2) -> 0.82644628 | R5: =MIN(R3/R4,2) -> 0.80991736 | S5: =T5 -> 1.5592287 | T5: =MIN(T3/(T4*3),2) -> 1.5592287 | U5: =MIN(U3/U4,2) -> 1.9338843 | V5: =MIN(V3/V4,2) -> 1.6147541 | W5: =X5 -> 1.9275362 | X5: =MIN(X3/(X4*3),2) -> 1.9275362 | Y5: =MIN(Y3/Y4,2) -> 2 | Z5: =MIN(Z3/Z4,2) -> 2 | AA5: =AB5 -> 2 | AB5: =MIN(AB3/(AB4*3),2) -> 2 | AC5: =MIN(AC3/AC4,2) -> 2 | AD5: =MIN(AD3/AD4,2) -> 2 | AE5: =AF5 -> 2 | AF5: =MIN(AF3/(AF4*3),2) -> 2
C6: YTD | E6: =AVERAGE($E$5:E5) -> 1.218543 | F6: =AVERAGE($E$5:F5) -> 1.2119205 | G6: =H5 -> 1.1103753 | I6: =(3*H5+I5)/4 -> 1.3327815 | J6: =(3*H5+I5+J5)/5 -> 1.4662252 | K6: =AVERAGE(H5,L5) -> 1.5518764 | M6: =(H5*3+L5*3+M5)/7 -> 1.615894 | N6: =(H5*3+L5*3+M5+N5)/8 -> 1.6326573 | O6: =AVERAGE(H5,L5,P5) -> 1.4771922 | Q6: =(H5*3+L5*3+P5*3+Q5)/10 -> 1.4121176 | R6: =(H5*3+L5*3+P5*3+Q5+R5)/11 -> 1.3573721 | S6: =AVERAGE(H5,L5,P5,T5) -> 1.4977013 | U6: =(SUM(3*T5,3*P5,3*L5,G5,F5))/12 -> 1.396156 | V6: =(SUM(3*T5,3*P5,3*L5,G5,U5))/12 -> 1.4568715 | W6: =AVERAGE(L5,P5,T5,X5) -> 1.7019915 | Y6: =(SUM(3*X5,3*T5,3*P5,K5,J5,Y5))/12 -> 1.6479076 | Z6: =(SUM(3*X5,3*T5,3*P5,K5,Y5,Z5))/12 -> 1.6479076 | AA6: =AVERAGE(P5,T5,X5,AB5) -> 1.7036471 | AC6: =(SUM(3*AB5,3*X5,3*T5,O5,N5,AC5))/12 -> 1.834329 | AD6: =(SUM(3*AB5,3*X5,3*T5,O5,AC5,AD5))/12 -> 1.8551623 | AE6: =AVERAGE(T5,X5,AB5,AF5) -> 1.8716912
C10: Q | D10: CARE Cards created by each employee with max of 6 during the quarter
C11: YTD Average Corrected | D11: Average CARE Cards for last 12 months based on Quarterly Calculations

Sheet Near Miss KPI Value
B1: Pillar | C1: KPI Name | D1: KPI Definition | E1: 2025 | N1: 2026
E2: 25-Apr | F2: 25-May | G2: 25-Jun | H2: 25-Jul | I2: 25-Aug | J2: 25-Sep | K2: 25-Oct | L2: 25-Nov | M2: 25-Dec | N2: 26-Jan | O2: 26-Feb | P2: 26-Mar | Q2: 26-Apr | R2: 26-May | S2: 46199 | T2: 46229 | U2: 46260 | V2: 46291 | W2: 46321 | X2: 46352 | Y2: 46382
B3: HSE | C3: # of Reported Near miss - Monthly | D3: KPI Guideline | E3: 114 | F3: 105 | G3: 80 | H3: 216 | I3: 247 | J3: 117 | K3: 283 | L3: 140 | M3: 122 | N3: 65 | O3: 46 | P3: 167 | Q3: 352 | R3: 49 | S3: 0
C4: # of Reported Near miss - YTD | E4: =SUM($E$3:E3) -> 114 | F4: =SUM($E$3:F3) -> 219 | G4: =SUM($E$3:G3) -> 299 | H4: =SUM($E$3:H3) -> 515 | I4: =SUM($E$3:I3) -> 762 | J4: =SUM($E$3:J3) -> 879 | K4: =SUM($E$3:K3) -> 1162 | L4: =SUM($E$3:L3) -> 1302 | ... P4: =SUM($E$3:P3) -> 1702 | Q4: =SUM(OFFSET(Q3,0,-11):Q3) -> 1940 | R4: =SUM(OFFSET(R3,0,-11):R3) -> 1884 | S4: =SUM(OFFSET(S3,0,-11):S3) -> 1804 | T4: =SUM(OFFSET(T3,0,-11):T3) -> 1588 | U4: =SUM(OFFSET(U3,0,-11):U3) -> 1341 | V4: =SUM(OFFSET(V3,0,-11):V3) -> 1224 | W4: =SUM(OFFSET(W3,0,-11):W3) -> 941 | X4: =SUM(OFFSET(X3,0,-11):X3) -> 801 | Y4: =SUM(OFFSET(Y3,0,-11):Y3) -> 679

Sheet Near Miss AutoCount
A2: Employee Status | B2: (Multiple Items)
A3: Near Miss | B3: Yes
A4: Status | B4: (Multiple Items)
A6: Count of Full Name / Nama Penuh
A7: 46

Sheet Value List
A1: 1 | B1: 2025
A2: 2 | B2: 2026
A3: 3
A4: 4
A5: 5
A6: 6
A7: 7
A8: 8
A9: 9
A10: 10
A11: 11
A12: 12
